Workbook

Sheet Resumen
A1: Resumen de sesión VR · P026
A3: Inicio: 2026-10-02 15:27:04 | Fuente: Metrics_P026_2026-10-02_15-27-04.txt
A5: Indicador | B5: Reportado en log | C5: Calculado de eventos | E5: Otros registros | F5: Cantidad | G5: Descripción
A6: Interacciones totales | B6: 223 | C6: =COUNTA('Interacciones'!$A$2:$A$224) -> 223 | E6: Cambios de dificultad | F6: 8 | G6: Eventos de adaptación de dificultad
A7: Aciertos (Success) | B7: 145 | C7: =COUNTIF('Interacciones'!$F$2:$F$224,"Success") -> 145 | E7: Estados del jugador | F7: 20 | G7: Cambios globales de estado
A8: Fallos (Failed) | B8: 46 | C8: =COUNTIF('Interacciones'!$F$2:$F$224,"Failed") -> 46 | E8: Eventos totales | F8: 251 | G8: Incluye todos los tipos de eventos
A9: Omisiones (Missed) | B9: 32 | C9: =COUNTIF('Interacciones'!$F$2:$F$224,"Missed") -> 32 | E9: Otros eventos | F9: 0 | G9: Eventos sin categoría estándar
A10: Tasa de éxito | B10: 0.6502 | C10: =IFERROR(C7/C6,0) -> 0.65022422
A11: Error timing medio (s) | B11: 0.2361 | C11: =IFERROR(AVERAGE('Interacciones'!$K$2:$K$224),"") -> 0.23608608
A12: Reacción media (s) | B12: 0.7304 | C12: =IFERROR(AVERAGE('Interacciones'!$L$2:$L$224),"") -> 0.73044118
A13: Precisión espacial media | B13: 0 | C13: =IFERROR(AVERAGE('Interacciones'!$M$2:$M$224),"")
A14: Precisión dirección media | B14: 0.6833 | C14: =IFERROR(AVERAGE('Interacciones'!$N$2:$N$224),"") -> 0.68333333
A16: Observaciones
A17: N/A se conserva como celda vacía: no equivale a cero.
A18: Si no hay valores de precisión espacial, el promedio recalculado queda vacío; el log puede reportar 0.
A19: Los estados del jugador no se asignan a minijuegos cuando el log no los identifica.
A20: Se cuentan eventos tal como aparecen, incluso si comparten marca temporal; no se eliminan duplicados.

Sheet Por minijuego
A1: Rendimiento por minijuego
A4: Minijuego | B4: Interacciones | C4: Aciertos | D4: Fallos | E4: Omitidos | F4: TasaExito | G4: ErrorMedio_s | H4: ReaccionMedia_s | I4: CambiosDDA | J4: AccionesRegistradas
A5: Alex | B5: =COUNTIF('Interacciones'!$D$2:$D$224,$A5) -> 120 | C5: =COUNTIFS('Interacciones'!$D$2:$D$224,$A5,'Interacciones'!$F$2:$F$224,"Success") -> 87 | D5: =COUNTIFS('Interacciones'!$D$2:$D$224,$A5,'Interacciones'!$F$2:$F$224,"Failed") -> 2 | E5: =COUNTIFS('Interacciones'!$D$2:$D$224,$A5,'Interacciones'!$F$2:$F$224,"Missed") -> 31 | F5: =IFERROR(C5/B5,0) -> 0.725 | G5: =IFERROR(AVERAGEIF('Interacciones'!$D$2:$D$224,$A5,'Interacciones'!$K$2:$K$224),"") -> 0.027244 | H5: =IFERROR(AVERAGEIF('Interacciones'!$D$2:$D$224,$A5,'Interacciones'!$L$2:$L$224),"") | I5: =COUNTIF('Adaptaciones'!$C$2:$C$9,$A5) -> 2 | J5: HammerHit, HammerTouch
A6: Danniel | B6: =COUNTIF('Interacciones'!$D$2:$D$224,$A6) -> 23 | C6: =COUNTIFS('Interacciones'!$D$2:$D$224,$A6,'Interacciones'!$F$2:$F$224,"Success") -> 9 | D6: =COUNTIFS('Interacciones'!$D$2:$D$224,$A6,'Interacciones'!$F$2:$F$224,"Failed") -> 14 | E6: =COUNTIFS('Interacciones'!$D$2:$D$224,$A6,'Interacciones'!$F$2:$F$224,"Missed") -> 0 | F6: =IFERROR(C6/B6,0) -> 0.39130435 | G6: =IFERROR(AVERAGEIF('Interacciones'!$D$2:$D$224,$A6,'Interacciones'!$K$2:$K$224),"") -> 0.10186667 | H6: =IFERROR(AVERAGEIF('Interacciones'!$D$2:$D$224,$A6,'Interacciones'!$L$2:$L$224),"") | I6: =COUNTIF('Adaptaciones'!$C$2:$C$9,$A6) -> 0 | J6: GunShoot, PlayerHit
A7: Jeremy | B7: =COUNTIF('Interacciones'!$D$2:$D$224,$A7) -> 8 | C7: =COUNTIFS('Interacciones'!$D$2:$D$224,$A7,'Interacciones'!$F$2:$F$224,"Success") -> 7 | D7: =COUNTIFS('Interacciones'!$D$2:$D$224,$A7,'Interacciones'!$F$2:$F$224,"Failed") -> 1 | E7: =COUNTIFS('Interacciones'!$D$2:$D$224,$A7,'Interacciones'!$F$2:$F$224,"Missed") -> 0 | F7: =IFERROR(C7/B7,0) -> 0.875 | G7: =IFERROR(AVERAGEIF('Interacciones'!$D$2:$D$224,$A7,'Interacciones'!$K$2:$K$224),"") -> 0.1262625 | H7: =IFERROR(AVERAGEIF('Interacciones'!$D$2:$D$224,$A7,'Interacciones'!$L$2:$L$224),"") | I7: =COUNTIF('Adaptaciones'!$C$2:$C$9,$A7) -> 1 | J7: SwordCut
A8: Joaquin | B8: =COUNTIF('Interacciones'!$D$2:$D$224,$A8) -> 16 | C8: =COUNTIFS('Interacciones'!$D$2:$D$224,$A8,'Interacciones'!$F$2:$F$224,"Success") -> 14 | D8: =COUNTIFS('Interacciones'!$D$2:$D$224,$A8,'Interacciones'!$F$2:$F$224,"Failed") -> 2 | E8: =COUNTIFS('Interacciones'!$D$2:$D$224,$A8,'Interacciones'!$F$2:$F$224,"Missed") -> 0 | F8: =IFERROR(C8/B8,0) -> 0.875 | G8: =IFERROR(AVERAGEIF('Interacciones'!$D$2:$D$224,$A8,'Interacciones'!$K$2:$K$224),"") -> 0.066857143 | H8: =IFERROR(AVERAGEIF('Interacciones'!$D$2:$D$224,$A8,'Interacciones'!$L$2:$L$224),"") | I8: =COUNTIF('Adaptaciones'!$C$2:$C$9,$A8) -> 1 | J8: GuitarHit, PlayerHit
A9: JuanAndres | B9: =COUNTIF('Interacciones'!$D$2:$D$224,$A9) -> 35 | C9: =COUNTIFS('Interacciones'!$D$2:$D$224,$A9,'Interacciones'!$F$2:$F$224,"Success") -> 14 | D9: =COUNTIFS('Interacciones'!$D$2:$D$224,$A9,'Interacciones'!$F$2:$F$224,"Failed") -> 21 | E9: =COUNTIFS('Interacciones'!$D$2:$D$224,$A9,'Interacciones'!$F$2:$F$224,"Missed") -> 0 | F9: =IFERROR(C9/B9,0) -> 0.4 | G9: =IFERROR(AVERAGEIF('Interacciones'!$D$2:$D$224,$A9,'Interacciones'!$K$2:$K$224),"") -> 0.80812857 | H9: =IFERROR(AVERAGEIF('Interacciones'!$D$2:$D$224,$A9,'Interacciones'!$L$2:$L$224),"") | I9: =COUNTIF('Adaptaciones'!$C$2:$C$9,$A9) -> 2 | J9: GroomStroke
A10: Shipi | B10: =COUNTIF('Interacciones'!$D$2:$D$224,$A10) -> 21 | C10: =COUNTIFS('Interacciones'!$D$2:$D$224,$A10,'Interacciones'!$F$2:$F$224,"Success") -> 14 | D10: =COUNTIFS('Interacciones'!$D$2:$D$224,$A10,'Interacciones'!$F$2:$F$224,"Failed") -> 6 | E10: =COUNTIFS('Interacciones'!$D$2:$D$224,$A10,'Interacciones'!$F$2:$F$224,"Missed") -> 1 | F10: =IFERROR(C10/B10,0) -> 0.66666667 | G10: =IFERROR(AVERAGEIF('Interacciones'!$D$2:$D$224,$A10,'Interacciones'!$K$2:$K$224),"") -> 0.24181765 | H10: =IFERROR(AVERAGEIF('Interacciones'!$D$2:$D$224,$A10,'Interacciones'!$L$2:$L$224),"") -> 0.73044118 | I10: =COUNTIF('Adaptaciones'!$C$2:$C$9,$A10) -> 2 | J10: FoodClear, FoodCut

Sheet Por accion
A1: Rendimiento por tipo de acción
A4: Minijuego | B4: TipoAccion | C4: Interacciones | D4: Aciertos | E4: Fallos | F4: Omitidos | G4: TasaExito | H4: ErrorMedio_s | I4: ReaccionMedia_s
A5: Alex | B5: HammerHit | C5: =COUNTIFS('Interacciones'!$D$2:$D$224,$A5,'Interacciones'!$E$2:$E$224,$B5) -> 81 | D5: =COUNTIFS('Interacciones'!$D$2:$D$224,$A5,'Interacciones'!$E$2:$E$224,$B5,'Interacciones'!$F$2:$F$224,"Success") -> 79 | E5: =COUNTIFS('Interacciones'!$D$2:$D$224,$A5,'Interacciones'!$E$2:$E$224,$B5,'Interacciones'!$F$2:$F$224,"Failed") -> 2 | F5: =COUNTIFS('Interacciones'!$D$2:$D$224,$A5,'Interacciones'!$E$2:$E$224,$B5,'Interacciones'!$F$2:$F$224,"Missed") -> 0 | G5: =IFERROR(D5/C5,0) -> 0.97530864 | H5: =IFERROR(AVERAGEIFS('Interacciones'!$K$2:$K$224,'Interacciones'!$D$2:$D$224,$A5,'Interacciones'!$E$2:$E$224,$B5),"") -> 0.027244 | I5: =IFERROR(AVERAGEIFS('Interacciones'!$L$2:$L$224,'Interacciones'!$D$2:$D$224,$A5,'Interacciones'!$E$2:$E$224,$B5),"")
A6: Alex | B6: HammerTouch | C6: =COUNTIFS('Interacciones'!$D$2:$D$224,$A6,'Interacciones'!$E$2:$E$224,$B6) -> 39 | D6: =COUNTIFS('Interacciones'!$D$2:$D$224,$A6,'Interacciones'!$E$2:$E$224,$B6,'Interacciones'!$F$2:$F$224,"Success") -> 8 | E6: =COUNTIFS('Interacciones'!$D$2:$D$224,$A6,'Interacciones'!$E$2:$E$224,$B6,'Interacciones'!$F$2:$F$224,"Failed") -> 0 | F6: =COUNTIFS('Interacciones'!$D$2:$D$224,$A6,'Interacciones'!$E$2:$E$224,$B6,'Interacciones'!$F$2:$F$224,"Missed") -> 31 | G6: =IFERROR(D6/C6,0) -> 0.20512821 | H6: =IFERROR(AVERAGEIFS('Interacciones'!$K$2:$K$224,'Interacciones'!$D$2:$D$224,$A6,'Interacciones'!$E$2:$E$224,$B6),"") | I6: =IFERROR(AVERAGEIFS('Interacciones'!$L$2:$L$224,'Interacciones'!$D$2:$D$224,$A6,'Interacciones'!$E$2:$E$224,$B6),"")
A7: Danniel | B7: GunShoot | C7: =COUNTIFS('Interacciones'!$D$2:$D$224,$A7,'Interacciones'!$E$2:$E$224,$B7) -> 22 | D7: =COUNTIFS('Interacciones'!$D$2:$D$224,$A7,'Interacciones'!$E$2:$E$224,$B7,'Interacciones'!$F$2:$F$224,"Success") -> 9 | E7: =COUNTIFS('Interacciones'!$D$2:$D$224,$A7,'Interacciones'!$E$2:$E$224,$B7,'Interacciones'!$F$2:$F$224,"Failed") -> 13 | F7: =COUNTIFS('Interacciones'!$D$2:$D$224,$A7,'Interacciones'!$E$2:$E$224,$B7,'Interacciones'!$F$2:$F$224,"Missed") -> 0 | G7: =IFERROR(D7/C7,0) -> 0.40909091 | H7: =IFERROR(AVERAGEIFS('Interacciones'!$K$2:$K$224,'Interacciones'!$D$2:$D$224,$A7,'Interacciones'!$E$2:$E$224,$B7),"") -> 0.10186667 | I7: =IFERROR(AVERAGEIFS('Interacciones'!$L$2:$L$224,'Interacciones'!$D$2:$D$224,$A7,'Interacciones'!$E$2:$E$224,$B7),"")
A8: Danniel | B8: PlayerHit | C8: =COUNTIFS('Interacciones'!$D$2:$D$224,$A8,'Interacciones'!$E$2:$E$224,$B8) -> 1 | D8: =COUNTIFS('Interacciones'!$D$2:$D$224,$A8,'Interacciones'!$E$2:$E$224,$B8,'Interacciones'!$F$2:$F$224,"Success") -> 0 | E8: =COUNTIFS('Interacciones'!$D$2:$D$224,$A8,'Interacciones'!$E$2:$E$224,$B8,'Interacciones'!$F$2:$F$224,"Failed") -> 1 | F8: =COUNTIFS('Interacciones'!$D$2:$D$224,$A8,'Interacciones'!$E$2:$E$224,$B8,'Interacciones'!$F$2:$F$224,"Missed") -> 0 | G8: =IFERROR(D8/C8,0) -> 0 | H8: =IFERROR(AVERAGEIFS('Interacciones'!$K$2:$K$224,'Interacciones'!$D$2:$D$224,$A8,'Interacciones'!$E$2:$E$224,$B8),"") | I8: =IFERROR(AVERAGEIFS('Interacciones'!$L$2:$L$224,'Interacciones'!$D$2:$D$224,$A8,'Interacciones'!$E$2:$E$224,$B8),"")
A9: Jeremy | B9: SwordCut | C9: =COUNTIFS('Interacciones'!$D$2:$D$224,$A9,'Interacciones'!$E$2:$E$224,$B9) -> 8 | D9: =COUNTIFS('Interacciones'!$D$2:$D$224,$A9,'Interacciones'!$E$2:$E$224,$B9,'Interacciones'!$F$2:$F$224,"Success") -> 7 | E9: =COUNTIFS('Interacciones'!$D$2:$D$224,$A9,'Interacciones'!$E$2:$E$224,$B9,'Interacciones'!$F$2:$F$224,"Failed") -> 1 | F9: =COUNTIFS('Interacciones'!$D$2:$D$224,$A9,'Interacciones'!$E$2:$E$224,$B9,'Interacciones'!$F$2:$F$224,"Missed") -> 0 | G9: =IFERROR(D9/C9,0) -> 0.875 | H9: =IFERROR(AVERAGEIFS('Interacciones'!$K$2:$K$224,'Interacciones'!$D$2:$D$224,$A9,'Interacciones'!$E$2:$E$224,$B9),"") -> 0.1262625 | I9: =IFERROR(AVERAGEIFS('Interacciones'!$L$2:$L$224,'Interacciones'!$D$2:$D$224,$A9,'Interacciones'!$E$2:$E$224,$B9),"")
A10: Joaquin | B10: GuitarHit | C10: =COUNTIFS('Interacciones'!$D$2:$D$224,$A10,'Interacciones'!$E$2:$E$224,$B10) -> 14 | D10: =COUNTIFS('Interacciones'!$D$2:$D$224,$A10,'Interacciones'!$E$2:$E$224,$B10,'Interacciones'!$F$2:$F$224,"Success") -> 14 | E10: =COUNTIFS('Interacciones'!$D$2:$D$224,$A10,'Interacciones'!$E$2:$E$224,$B10,'Interacciones'!$F$2:$F$224,"Failed") -> 0 | F10: =COUNTIFS('Interacciones'!$D$2:$D$224,$A10,'Interacciones'!$E$2:$E$224,$B10,'Interacciones'!$F$2:$F$224,"Missed") -> 0 | G10: =IFERROR(D10/C10,0) -> 1 | H10: =IFERROR(AVERAGEIFS('Interacciones'!$K$2:$K$224,'Interacciones'!$D$2:$D$224,$A10,'Interacciones'!$E$2:$E$224,$B10),"") -> 0.066857143 | I10: =IFERROR(AVERAGEIFS('Interacciones'!$L$2:$L$224,'Interacciones'!$D$2:$D$224,$A10,'Interacciones'!$E$2:$E$224,$B10),"")
A11: Joaquin | B11: PlayerHit | C11: =COUNTIFS('Interacciones'!$D$2:$D$224,$A11,'Interacciones'!$E$2:$E$224,$B11) -> 2 | D11: =COUNTIFS('Interacciones'!$D$2:$D$224,$A11,'Interacciones'!$E$2:$E$224,$B11,'Interacciones'!$F$2:$F$224,"Success") -> 0 | E11: =COUNTIFS('Interacciones'!$D$2:$D$224,$A11,'Interacciones'!$E$2:$E$224,$B11,'Interacciones'!$F$2:$F$224,"Failed") -> 2 | F11: =COUNTIFS('Interacciones'!$D$2:$D$224,$A11,'Interacciones'!$E$2:$E$224,$B11,'Interacciones'!$F$2:$F$224,"Missed") -> 0 | G11: =IFERROR(D11/C11,0) -> 0 | H11: =IFERROR(AVERAGEIFS('Interacciones'!$K$2:$K$224,'Interacciones'!$D$2:$D$224,$A11,'Interacciones'!$E$2:$E$224,$B11),"") | I11: =IFERROR(AVERAGEIFS('Interacciones'!$L$2:$L$224,'Interacciones'!$D$2:$D$224,$A11,'Interacciones'!$E$2:$E$224,$B11),"")
A12: JuanAndres | B12: GroomStroke | C12: =COUNTIFS('Interacciones'!$D$2:$D$224,$A12,'Interacciones'!$E$2:$E$224,$B12) -> 35 | D12: =COUNTIFS('Interacciones'!$D$2:$D$224,$A12,'Interacciones'!$E$2:$E$224,$B12,'Interacciones'!$F$2:$F$224,"Success") -> 14 | E12: =COUNTIFS('Interacciones'!$D$2:$D$224,$A12,'Interacciones'!$E$2:$E$224,$B12,'Interacciones'!$F$2:$F$224,"Failed") -> 21 | F12: =COUNTIFS('Interacciones'!$D$2:$D$224,$A12,'Interacciones'!$E$2:$E$224,$B12,'Interacciones'!$F$2:$F$224,"Missed") -> 0 | G12: =IFERROR(D12/C12,0) -> 0.4 | H12: =IFERROR(AVERAGEIFS('Interacciones'!$K$2:$K$224,'Interacciones'!$D$2:$D$224,$A12,'Interacciones'!$E$2:$E$224,$B12),"") -> 0.80812857 | I12: =IFERROR(AVERAGEIFS('Interacciones'!$L$2:$L$224,'Interacciones'!$D$2:$D$224,$A12,'Interacciones'!$E$2:$E$224,$B12),"")
A13: Shipi | B13: FoodClear | C13: =COUNTIFS('Interacciones'!$D$2:$D$224,$A13,'Interacciones'!$E$2:$E$224,$B13) -> 2 | D13: =COUNTIFS('Interacciones'!$D$2:$D$224,$A13,'Interacciones'!$E$2:$E$224,$B13,'Interacciones'!$F$2:$F$224,"Success") -> 2 | E13: =COUNTIFS('Interacciones'!$D$2:$D$224,$A13,'Interacciones'!$E$2:$E$224,$B13,'Interacciones'!$F$2:$F$224,"Failed") -> 0 | F13: =COUNTIFS('Interacciones'!$D$2:$D$224,$A13,'Interacciones'!$E$2:$E$224,$B13,'Interacciones'!$F$2:$F$224,"Missed") -> 0 | G13: =IFERROR(D13/C13,0) -> 1 | H13: =IFERROR(AVERAGEIFS('Interacciones'!$K$2:$K$224,'Interacciones'!$D$2:$D$224,$A13,'Interacciones'!$E$2:$E$224,$B13),"") | I13: =IFERROR(AVERAGEIFS('Interacciones'!$L$2:$L$224,'Interacciones'!$D$2:$D$224,$A13,'Interacciones'!$E$2:$E$224,$B13),"")
A14: Shipi | B14: FoodCut | C14: =COUNTIFS('Interacciones'!$D$2:$D$224,$A14,'Interacciones'!$E$2:$E$224,$B14) -> 19 | D14: =COUNTIFS('Interacciones'!$D$2:$D$224,$A14,'Interacciones'!$E$2:$E$224,$B14,'Interacciones'!$F$2:$F$224,"Success") -> 12 | E14: =COUNTIFS('Interacciones'!$D$2:$D$224,$A14,'Interacciones'!$E$2:$E$224,$B14,'Interacciones'!$F$2:$F$224,"Failed") -> 6 | F14: =COUNTIFS('Interacciones'!$D$2:$D$224,$A14,'Interacciones'!$E$2:$E$224,$B14,'Interacciones'!$F$2:$F$224,"Missed") -> 1 | G14: =IFERROR(D14/C14,0) -> 0.63157895 | H14: =IFERROR(AVERAGEIFS('Interacciones'!$K$2:$K$224,'Interacciones'!$D$2:$D$224,$A14,'Interacciones'!$E$2:$E$224,$B14),"") -> 0.24181765 | I14: =IFERROR(AVERAGEIFS('Interacciones'!$L$2:$L$224,'Interacciones'!$D$2:$D$224,$A14,'Interacciones'!$E$2:$E$224,$B14),"") -> 0.73044118

Sheet Interacciones
A1: IdEvento | B1: Participante | C1: FechaHora | D1: Minijuego | E1: TipoAccion | F1: Resultado | G1: Dificultad | H1: TiempoEsperado_s | I1: TiempoReal_s | J1: DesfaseTiming_s | K1: ErrorTiming_s | L1: TiempoReaccion_s | M1: PrecisionEspacial | N1: PrecisionDireccion | O1: ManoCorrecta | P1: LineaOrigen
A2: 2 | B2: P026 | C2: 2026-10-02 15:27:07.405 | D2: Alex | E2: HammerHit | F2: Success | G2: Normal | H2: 0.896 | I2: 0.9043 | J2: 0.0083 | K2: 0.0083 | P2: 7
A3: 4 | B3: P026 | C3: 2026-10-02 15:27:08.143 | D3: Alex | E3: HammerHit | F3: Success | G3: Normal | H3: 1.664 | I3: 1.6422 | J3: -0.0218 | K3: 0.0218 | P3: 9
A4: 5 | B4: P026 | C4: 2026-10-02 15:27:08.170 | D4: Alex | E4: HammerHit | F4: Failed | G4: Normal | H4: 1.664 | I4: 1.6698 | J4: 0.0058 | K4: 0.0058 | P4: 10
A5: 6 | B5: P026 | C5: 2026-10-02 15:27:08.908 | D5: Alex | E5: HammerHit | F5: Success | G5: Normal | H5: 2.432 | I5: 2.4078 | J5: -0.0242 | K5: 0.0242 | P5: 11
A6: 7 | B6: P026 | C6: 2026-10-02 15:27:08.963 | D6: Alex | E6: HammerTouch | F6: Success | G6: Normal | H6: 2.432 | P6: 12
A7: 8 | B7: P026 | C7: 2026-10-02 15:27:09.646 | D7: Alex | E7: HammerHit | F7: Success | G7: Normal | H7: 3.2 | I7: 3.1458 | J7: -0.0542 | K7: 0.0542 | P7: 13
A8: 9 | B8: P026 | C8: 2026-10-02 15:27:09.743 | D8: Alex | E8: HammerTouch | F8: Success | G8: Normal | H8: 3.2 | P8: 14
A9: 10 | B9: P026 | C9: 2026-10-02 15:27:10.439 | D9: Alex | E9: HammerHit | F9: Success | G9: Normal | H9: 3.968 | I9: 3.9393 | J9: -0.0287 | K9: 0.0287 | P9: 15
A10: 12 | B10: P026 | C10: 2026-10-02 15:27:11.191 | D10: Alex | E10: HammerTouch | F10: Success | G10: Hard | H10: 4.736 | P10: 17
A11: 13 | B11: P026 | C11: 2026-10-02 15:27:11.566 | D11: Alex | E11: HammerTouch | F11: Missed | G11: Hard | H11: 4.736 | P11: 18
A12: 14 | B12: P026 | C12: 2026-10-02 15:27:11.582 | D12: Alex | E12: HammerHit | F12: Success | G12: Hard | H12: 5.12 | I12: 5.0812 | J12: -0.0388 | K12: 0.0388 | P12: 19
A13: 15 | B13: P026 | C13: 2026-10-02 15:27:11.986 | D13: Alex | E13: HammerHit | F13: Success | G13: Hard | H13: 5.504 | I13: 5.4849 | J13: -0.0191 | K13: 0.0191 | P13: 20
A14: 16 | B14: P026 | C14: 2026-10-02 15:27:12.333 | D14: Alex | E14: HammerTouch | F14: Missed | G14: Hard | H14: 5.504 | P14: 21
A15: 17 | B15: P026 | C15: 2026-10-02 15:27:12.362 | D15: Alex | E15: HammerHit | F15: Success | G15: Hard | H15: 5.888 | I15: 5.8608 | J15: -0.0272 | K15: 0.0272 | P15: 22
A16: 18 | B16: P026 | C16: 2026-10-02 15:27:12.765 | D16: Alex | E16: HammerHit | F16: Success | G16: Hard | H16: 6.272 | I16: 6.2646 | J16: -0.0074 | K16: 0.0074 | P16: 23
A17: 19 | B17: P026 | C17: 2026-10-02 15:27:12.835 | D17: Alex | E17: HammerHit | F17: Success | G17: Hard | H17: 6.272 | I17: 6.3342 | J17: 0.0622 | K17: 0.0622 | P17: 24
A18: 20 | B18: P026 | C18: 2026-10-02 15:27:13.142 | D18: Alex | E18: HammerHit | F18: Success | G18: Hard | H18: 6.656 | I18: 6.6409 | J18: -0.0151 | K18: 0.0151 | P18: 25
A19: 21 | B19: P026 | C19: 2026-10-02 15:27:13.531 | D19: Alex | E19: HammerHit | F19: Success | G19: Hard | H19: 7.04 | I19: 7.0309 | J19: -0.0091 | K19: 0.0091 | P19: 26
A20: 22 | B20: P026 | C20: 2026-10-02 15:27:13.864 | D20: Alex | E20: HammerTouch | F20: Missed | G20: Hard | H20: 7.04 | P20: 27
A21: 23 | B21: P026 | C21: 2026-10-02 15:27:13.866 | D21: Alex | E21: HammerHit | F21: Success | G21: Hard | H21: 7.424 | I21: 7.3652 | J21: -0.0588 | K21: 0.0588 | P21: 28
A22: 24 | B22: P026 | C22: 2026-10-02 15:27:14.270 | D22: Alex | E22: HammerHit | F22: Success | G22: Hard | H22: 7.808 | I22: 7.7691 | J22: -0.0389 | K22: 0.0389 | P22: 29
A23: 25 | B23: P026 | C23: 2026-10-02 15:27:14.630 | D23: Alex | E23: HammerTouch | F23: Missed | G23: Hard | H23: 7.808 | P23: 30
A24: 26 | B24: P026 | C24: 2026-10-02 15:27:14.646 | D24: Alex | E24: HammerHit | F24: Success | G24: Hard | H24: 8.192 | I24: 8.1454 | J24: -0.0466 | K24: 0.0466 | P24: 31
A25: 27 | B25: P026 | C25: 2026-10-02 15:27:14.688 | D25: Alex | E25: HammerHit | F25: Success | G25: Hard | H25: 8.192 | P25: 32
A26: 28 | B26: P026 | C26: 2026-10-02 15:27:15.064 | D26: Alex | E26: HammerHit | F26: Success | G26: Hard | H26: 8.576 | I26: 8.5629 | J26: -0.0131 | K26: 0.0131 | P26: 33
A27: 29 | B27: P026 | C27: 2026-10-02 15:27:15.410 | D27: Alex | E27: HammerTouch | F27: Missed | G27: Hard | H27: 8.576 | P27: 34
A28: 30 | B28: P026 | C28: 2026-10-02 15:27:15.453 | D28: Alex | E28: HammerHit | F28: Success | G28: Hard | H28: 8.96 | I28: 8.9527 | J28: -0.0073 | K28: 0.0073 | P28: 35
A29: 31 | B29: P026 | C29: 2026-10-02 15:27:15.564 | D29: Alex | E29: HammerHit | F29: Success | G29: Hard | H29: 8.96 | P29: 36
A30: 32 | B30: P026 | C30: 2026-10-02 15:27:15.801 | D30: Alex | E30: HammerHit | F30: Success | G30: Hard | H30: 9.344 | I30: 9.3008 | J30: -0.0432 | K30: 0.0432 | P30: 37
A31: 33 | B31: P026 | C31: 2026-10-02 15:27:15.829 | D31: Alex | E31: HammerTouch | F31: Success | G31: Hard | H31: 9.344 | P31: 38
A32: 34 | B32: P026 | C32: 2026-10-02 15:27:16.164 | D32: Alex | E32: HammerHit | F32: Success | G32: Hard | H32: 9.728 | I32: 9.663 | J32: -0.065 | K32: 0.065 | P32: 39
A33: 35 | B33: P026 | C33: 2026-10-02 15:27:16.609 | D33: Alex | E33: HammerHit | F33: Success | G33: Hard | H33: 10.112 | I33: 10.1085 | J33: -0.0035 | K33: 0.0035 | P33: 40
A34: 36 | B34: P026 | C34: 2026-10-02 15:27:16.929 | D34: Alex | E34: HammerTouch | F34: Missed | G34: Hard | H34: 10.112 | P34: 41
A35: 37 | B35: P026 | C35: 2026-10-02 15:27:16.970 | D35: Alex | E35: HammerHit | F35: Success | G35: Hard | H35: 10.496 | I35: 10.4707 | J35: -0.0253 | K35: 0.0253 | P35: 42
A36: 38 | B36: P026 | C36: 2026-10-02 15:27:17.013 | D36: Alex | E36: HammerHit | F36: Success | G36: Hard | H36: 10.496 | P36: 43
A37: 39 | B37: P026 | C37: 2026-10-02 15:27:17.360 | D37: Alex | E37: HammerHit | F37: Success | G37: Hard | H37: 10.88 | I37: 10.8602 | J37: -0.0198 | K37: 0.0198 | P37: 44
A38: 40 | B38: P026 | C38: 2026-10-02 15:27:17.708 | D38: Alex | E38: HammerTouch | F38: Missed | G38: Hard | H38: 10.88 | P38: 45
A39: 41 | B39: P026 | C39: 2026-10-02 15:27:17.723 | D39: Alex | E39: HammerHit | F39: Success | G39: Hard | H39: 11.264 | I39: 11.2223 | J39: -0.0417 | K39: 0.0417 | P39: 46
A40: 42 | B40: P026 | C40: 2026-10-02 15:27:18.071 | D40: Alex | E40: HammerHit | F40: Success | G40: Hard | H40: 11.648 | I40: 11.5703 | J40: -0.0777 | K40: 0.0777 | P40: 47
...

Sheet Adaptaciones
A1: IdEvento | B1: FechaHora | C1: Minijuego | D1: DificultadAnterior | E1: DificultadNueva | F1: Motivo | G1: TasaExitoReciente | H1: TasaExito | I1: LineaOrigen
A2: 11 | B2: 2026-10-02 15:27:10.441 | C2: Alex | D2: Normal | E2: Hard | F2: High recent performance | H2: 0.88 | I2: 16
A3: 123 | B3: 2026-10-02 15:27:37.283 | C3: Alex | D3: Hard | E3: Normal | F3: PlayerState: Overloaded | G3: 0.5 | I3: 128
A4: 135 | B4: 2026-10-02 15:27:56.552 | C4: Joaquin | D4: Normal | E4: Hard | F4: High recent performance | H4: 1 | I4: 140
A5: 150 | B5: 2026-10-02 15:28:16.893 | C5: Shipi | D5: Hard | E5: Normal | F5: PlayerState: Overloaded | G5: 0.25 | I5: 155
A6: 162 | B6: 2026-10-02 15:28:32.918 | C6: Shipi | D6: Normal | E6: Hard | F6: High recent performance | H6: 1 | I6: 167
A7: 187 | B7: 2026-10-02 15:28:55.613 | C7: JuanAndres | D7: Hard | E7: Normal | F7: PlayerState: Overloaded | G7: 0.63 | I7: 192
A8: 207 | B8: 2026-10-02 15:29:07.668 | C8: JuanAndres | D8: Normal | E8: Easy | F8: PlayerState: Overloaded | G8: 0.5 | I8: 212
A9: 250 | B9: 2026-10-02 15:30:09.093 | C9: Jeremy | D9: Easy | E9: Normal | F9: High recent performance | H9: 0.88 | I9: 255

Sheet Estados jugador
A1: IdEvento | B1: FechaHora | C1: EstadoJugador | D1: LineaOrigen
A2: 1 | B2: 2026-10-02 15:27:06.513 | C2: Idle | D2: 6
A3: 3 | B3: 2026-10-02 15:27:07.405 | C3: Engaged | D3: 8
A4: 122 | B4: 2026-10-02 15:27:37.283 | C4: Overloaded | D4: 127
A5: 124 | B5: 2026-10-02 15:27:37.284 | C5: Engaged | D5: 129
A6: 149 | B6: 2026-10-02 15:28:16.893 | C6: Overloaded | D6: 154
A7: 151 | B7: 2026-10-02 15:28:16.894 | C7: Engaged | D7: 156
A8: 186 | B8: 2026-10-02 15:28:55.612 | C8: Overloaded | D8: 191
A9: 188 | B9: 2026-10-02 15:28:55.614 | C9: Engaged | D9: 193
A10: 196 | B10: 2026-10-02 15:29:00.607 | C10: Idle | D10: 201
A11: 201 | B11: 2026-10-02 15:29:04.006 | C11: Engaged | D11: 206
A12: 206 | B12: 2026-10-02 15:29:07.668 | C12: Overloaded | D12: 211
A13: 208 | B13: 2026-10-02 15:29:07.668 | C13: Engaged | D13: 213
... A21: 251 | B21: 2026-10-02 15:30:14.091 | C21: Idle | D21: 256

Sheet Todos eventos
A1: IdEvento | B1: FechaHora | C1: Categoria | D1: Minijuego | E1: TipoAccion | F1: Resultado | G1: Dificultad | H1: EstadoJugador | I1: CambioDificultad | J1: Motivo | K1: ErrorTiming_s | L1: TiempoReaccion_s | M1: LineaOrigen | N1: TextoOriginal
A2: 1 | B2: 2026-10-02 15:27:06.513 | C2: PlayerState | H2: Idle | M2: 6 | N2: 2026-10-02 15:27:06.513 | PlayerState: Idle
A3: 2 | B3: 2026-10-02 15:27:07.405 | C3: Interaction | D3: Alex | E3: HammerHit | F3: Success | G3: Normal | K3: 0.0083 | M3: 7 | N3: 2026-10-02 15:27:07.405 | Minigame: Alex | Type: HammerHit | Outcome: Success | Difficulty: Normal | ExpectedTime: 0.8960 | ActualTime: 0.9043 | TimingOffset: 0.0083 | TimingError: 0.0083 | ReactionTime: N/A | SpatialAccuracy: N/A | DirectionAccuracy: N/A | CorrectHand: N/A
A4: 3 | B4: 2026-10-02 15:27:07.405 | C4: PlayerState | H4: Engaged | M4: 8 | N4: 2026-10-02 15:27:07.405 | PlayerState: Engaged
A5: 4 | B5: 2026-10-02 15:27:08.143 | C5: Interaction | D5: Alex | E5: HammerHit | F5: Success | G5: Normal | K5: 0.0218 | M5: 9 | N5: 2026-10-02 15:27:08.143 | Minigame: Alex | Type: HammerHit | Outcome: Success | Difficulty: Normal | ExpectedTime: 1.6640 | ActualTime: 1.6422 | TimingOffset: -0.0218 | TimingError: 0.0218 | ReactionTime: N/A | SpatialAccuracy: N/A | DirectionAccuracy: N/A | CorrectHand: N/A
A6: 5 | B6: 2026-10-02 15:27:08.170 | C6: Interaction | D6: Alex | E6: HammerHit | F6: Failed | G6: Normal | K6: 0.0058 | M6: 10 | N6: 2026-10-02 15:27:08.170 | Minigame: Alex | Type: HammerHit | Outcome: Failed | Difficulty: Normal | ExpectedTime: 1.6640 | ActualTime: 1.6698 | TimingOffset: 0.0058 | TimingError: 0.0058 | ReactionTime: N/A | SpatialAccuracy: N/A | DirectionAccuracy: N/A | CorrectHand: N/A
A7: 6 | B7: 2026-10-02 15:27:08.908 | C7: Interaction | D7: Alex | E7: HammerHit | F7: Success | G7: Normal | K7: 0.0242 | M7: 11 | N7: 2026-10-02 15:27:08.908 | Minigame: Alex | Type: HammerHit | Outcome: Success | Difficulty: Normal | ExpectedTime: 2.4320 | ActualTime: 2.4078 | TimingOffset: -0.0242 | TimingError: 0.0242 | ReactionTime: N/A | SpatialAccuracy: N/A | DirectionAccuracy: N/A | CorrectHand: N/A
A8: 7 | B8: 2026-10-02 15:27:08.963 | C8: Interaction | D8: Alex | E8: HammerTouch | F8: Success | G8: Normal | M8: 12 | N8: 2026-10-02 15:27:08.963 | Minigame: Alex | Type: HammerTouch | Outcome: Success | Difficulty: Normal | ExpectedTime: 2.4320 | ActualTime: N/A | TimingOffset: N/A | TimingError: N/A | ReactionTime: N/A | SpatialAccuracy: N/A | DirectionAccuracy: N/A | CorrectHand: N/A
A9: 8 | B9: 2026-10-02 15:27:09.646 | C9: Interaction | D9: Alex | E9: HammerHit | F9: Success | G9: Normal | K9: 0.0542 | M9: 13 | N9: 2026-10-02 15:27:09.646 | Minigame: Alex | Type: HammerHit | Outcome: Success | Difficulty: Normal | ExpectedTime: 3.2000 | ActualTime: 3.1458 | TimingOffset: -0.0542 | TimingError: 0.0542 | ReactionTime: N/A | SpatialAccuracy: N/A | DirectionAccuracy: N/A | CorrectHand: N/A
A10: 9 | B10: 2026-10-02 15:27:09.743 | C10: Interaction | D10: Alex | E10: HammerTouch | F10: Success | G10: Normal | M10: 14 | N10: 2026-10-02 15:27:09.743 | Minigame: Alex | Type: HammerTouch | Outcome: Success | Difficulty: Normal | ExpectedTime: 3.2000 | ActualTime: N/A | TimingOffset: N/A | TimingError: N/A | ReactionTime: N/A | SpatialAccuracy: N/A | DirectionAccuracy: N/A | CorrectHand: N/A
A11: 10 | B11: 2026-10-02 15:27:10.439 | C11: Interaction | D11: Alex | E11: HammerHit | F11: Success | G11: Normal | K11: 0.0287 | M11: 15 | N11: 2026-10-02 15:27:10.439 | Minigame: Alex | Type: HammerHit | Outcome: Success | Difficulty: Normal | ExpectedTime: 3.9680 | ActualTime: 3.9393 | TimingOffset: -0.0287 | TimingError: 0.0287 | ReactionTime: N/A | SpatialAccuracy: N/A | DirectionAccuracy: N/A | CorrectHand: N/A
A12: 11 | B12: 2026-10-02 15:27:10.441 | C12: DifficultyChanged | D12: Alex | I12: Normal -> Hard | J12: High recent performance | M12: 16 | N12: 2026-10-02 15:27:10.441 | DifficultyChanged: Normal -> Hard | Reason: High recent performance | Minigame: Alex | SuccessRate: 0.88
A13: 12 | B13: 2026-10-02 15:27:11.191 | C13: Interaction | D13: Alex | E13: HammerTouch | F13: Success | G13: Hard | M13: 17 | N13: 2026-10-02 15:27:11.191 | Minigame: Alex | Type: HammerTouch | Outcome: Success | Difficulty: Hard | ExpectedTime: 4.7360 | ActualTime: N/A | TimingOffset: N/A | TimingError: N/A | ReactionTime: N/A | SpatialAccuracy: N/A | DirectionAccuracy: N/A | CorrectHand: N/A
A14: 13 | B14: 2026-10-02 15:27:11.566 | C14: Interaction | D14: Alex | E14: HammerTouch | F14: Missed | G14: Hard | M14: 18 | N14: 2026-10-02 15:27:11.566 | Minigame: Alex | Type: HammerTouch | Outcome: Missed | Difficulty: Hard | ExpectedTime: 4.7360 | ActualTime: N/A | TimingOffset: N/A | TimingError: N/A | ReactionTime: N/A | SpatialAccuracy: N/A | DirectionAccuracy: N/A | CorrectHand: N/A
A15: 14 | B15: 2026-10-02 15:27:11.582 | C15: Interaction | D15: Alex | E15: HammerHit | F15: Success | G15: Hard | K15: 0.0388 | M15: 19 | N15: 2026-10-02 15:27:11.582 | Minigame: Alex | Type: HammerHit | Outcome: Success | Difficulty: Hard | ExpectedTime: 5.1200 | ActualTime: 5.0812 | TimingOffset: -0.0388 | TimingError: 0.0388 | ReactionTime: N/A | SpatialAccuracy: N/A | DirectionAccuracy: N/A | CorrectHand: N/A
A16: 15 | B16: 2026-10-02 15:27:11.986 | C16: Interaction | D16: Alex | E16: HammerHit | F16: Success | G16: Hard | K16: 0.0191 | M16: 20 | N16: 2026-10-02 15:27:11.986 | Minigame: Alex | Type: HammerHit | Outcome: Success | Difficulty: Hard | ExpectedTime: 5.5040 | ActualTime: 5.4849 | TimingOffset: -0.0191 | TimingError: 0.0191 | ReactionTime: N/A | SpatialAccuracy: N/A | DirectionAccuracy: N/A | CorrectHand: N/A
A17: 16 | B17: 2026-10-02 15:27:12.333 | C17: Interaction | D17: Alex | E17: HammerTouch | F17: Missed | G17: Hard | M17: 21 | N17: 2026-10-02 15:27:12.333 | Minigame: Alex | Type: HammerTouch | Outcome: Missed | Difficulty: Hard | ExpectedTime: 5.5040 | ActualTime: N/A | TimingOffset: N/A | TimingError: N/A | ReactionTime: N/A | SpatialAccuracy: N/A | DirectionAccuracy: N/A | CorrectHand: N/A
A18: 17 | B18: 2026-10-02 15:27:12.362 | C18: Interaction | D18: Alex | E18: HammerHit | F18: Success | G18: Hard | K18: 0.0272 | M18: 22 | N18: 2026-10-02 15:27:12.362 | Minigame: Alex | Type: HammerHit | Outcome: Success | Difficulty: Hard | ExpectedTime: 5.8880 | ActualTime: 5.8608 | TimingOffset: -0.0272 | TimingError: 0.0272 | ReactionTime: N/A | SpatialAccuracy: N/A | DirectionAccuracy: N/A | CorrectHand: N/A
A19: 18 | B19: 2026-10-02 15:27:12.765 | C19: Interaction | D19: Alex | E19: HammerHit | F19: Success | G19: Hard | K19: 0.0074 | M19: 23 | N19: 2026-10-02 15:27:12.765 | Minigame: Alex | Type: HammerHit | Outcome: Success | Difficulty: Hard | ExpectedTime: 6.2720 | ActualTime: 6.2646 | TimingOffset: -0.0074 | TimingError: 0.0074 | ReactionTime: N/A | SpatialAccuracy: N/A | DirectionAccuracy: N/A | CorrectHand: N/A
A20: 19 | B20: 2026-10-02 15:27:12.835 | C20: Interaction | D20: Alex | E20: HammerHit | F20: Success | G20: Hard | K20: 0.0622 | M20: 24 | N20: 2026-10-02 15:27:12.835 | Minigame: Alex | Type: HammerHit | Outcome: Success | Difficulty: Hard | ExpectedTime: 6.2720 | ActualTime: 6.3342 | TimingOffset: 0.0622 | TimingError: 0.0622 | ReactionTime: N/A | SpatialAccuracy: N/A | DirectionAccuracy: N/A | CorrectHand: N/A
A21: 20 | B21: 2026-10-02 15:27:13.142 | C21: Interaction | D21: Alex | E21: HammerHit | F21: Success | G21: Hard | K21: 0.0151 | M21: 25 | N21: 2026-10-02 15:27:13.142 | Minigame: Alex | Type: HammerHit | Outcome: Success | Difficulty: Hard | ExpectedTime: 6.6560 | ActualTime: 6.6409 | TimingOffset: -0.0151 | TimingError: 0.0151 | ReactionTime: N/A | SpatialAccuracy: N/A | DirectionAccuracy: N/A | CorrectHand: N/A
A22: 21 | B22: 2026-10-02 15:27:13.531 | C22: Interaction | D22: Alex | E22: HammerHit | F22: Success | G22: Hard | K22: 0.0091 | M22: 26 | N22: 2026-10-02 15:27:13.531 | Minigame: Alex | Type: HammerHit | Outcome: Success | Difficulty: Hard | ExpectedTime: 7.0400 | ActualTime: 7.0309 | TimingOffset: -0.0091 | TimingError: 0.0091 | ReactionTime: N/A | SpatialAccuracy: N/A | DirectionAccuracy: N/A | CorrectHand: N/A
A23: 22 | B23: 2026-10-02 15:27:13.864 | C23: Interaction | D23: Alex | E23: HammerTouch | F23: Missed | G23: Hard | M23: 27 | N23: 2026-10-02 15:27:13.864 | Minigame: Alex | Type: HammerTouch | Outcome: Missed | Difficulty: Hard | ExpectedTime: 7.0400 | ActualTime: N/A | TimingOffset: N/A | TimingError: N/A | ReactionTime: N/A | SpatialAccuracy: N/A | DirectionAccuracy: N/A | CorrectHand: N/A
A24: 23 | B24: 2026-10-02 15:27:13.866 | C24: Interaction | D24: Alex | E24: HammerHit | F24: Success | G24: Hard | K24: 0.0588 | M24: 28 | N24: 2026-10-02 15:27:13.866 | Minigame: Alex | Type: HammerHit | Outcome: Success | Difficulty: Hard | ExpectedTime: 7.4240 | ActualTime: 7.3652 | TimingOffset: -0.0588 | TimingError: 0.0588 | ReactionTime: N/A | SpatialAccuracy: N/A | DirectionAccuracy: N/A | CorrectHand: N/A
A25: 24 | B25: 2026-10-02 15:27:14.270 | C25: Interaction | D25: Alex | E25: HammerHit | F25: Success | G25: Hard | K25: 0.0389 | M25: 29 | N25: 2026-10-02 15:27:14.270 | Minigame: Alex | Type: HammerHit | Outcome: Success | Difficulty: Hard | ExpectedTime: 7.8080 | ActualTime: 7.7691 | TimingOffset: -0.0389 | TimingError: 0.0389 | ReactionTime: N/A | SpatialAccuracy: N/A | DirectionAccuracy: N/A | CorrectHand: N/A
A26: 25 | B26: 2026-10-02 15:27:14.630 | C26: Interaction | D26: Alex | E26: HammerTouch | F26: Missed | G26: Hard | M26: 30 | N26: 2026-10-02 15:27:14.630 | Minigame: Alex | Type: HammerTouch | Outcome: Missed | Difficulty: Hard | ExpectedTime: 7.8080 | ActualTime: N/A | TimingOffset: N/A | TimingError: N/A | ReactionTime: N/A | SpatialAccuracy: N/A | DirectionAccuracy: N/A | CorrectHand: N/A
A27: 26 | B27: 2026-10-02 15:27:14.646 | C27: Interaction | D27: Alex | E27: HammerHit | F27: Success | G27: Hard | K27: 0.0466 | M27: 31 | N27: 2026-10-02 15:27:14.646 | Minigame: Alex | Type: HammerHit | Outcome: Success | Difficulty: Hard | ExpectedTime: 8.1920 | ActualTime: 8.1454 | TimingOffset: -0.0466 | TimingError: 0.0466 | ReactionTime: N/A | SpatialAccuracy: N/A | DirectionAccuracy: N/A | CorrectHand: N/A
A28: 27 | B28: 2026-10-02 15:27:14.688 | C28: Interaction | D28: Alex | E28: HammerHit | F28: Success | G28: Hard | M28: 32 | N28: 2026-10-02 15:27:14.688 | Minigame: Alex | Type: HammerHit | Outcome: Success | Difficulty: Hard | ExpectedTime: 8.1920 | ActualTime: N/A | TimingOffset: N/A | TimingError: N/A | ReactionTime: N/A | SpatialAccuracy: N/A | DirectionAccuracy: N/A | CorrectHand: N/A
A29: 28 | B29: 2026-10-02 15:27:15.064 | C29: Interaction | D29: Alex | E29: HammerHit | F29: Success | G29: Hard | K29: 0.0131 | M29: 33 | N29: 2026-10-02 15:27:15.064 | Minigame: Alex | Type: HammerHit | Outcome: Success | Difficulty: Hard | ExpectedTime: 8.5760 | ActualTime: 8.5629 | TimingOffset: -0.0131 | TimingError: 0.0131 | ReactionTime: N/A | SpatialAccuracy: N/A | DirectionAccuracy: N/A | CorrectHand: N/A
A30: 29 | B30: 2026-10-02 15:27:15.410 | C30: Interaction | D30: Alex | E30: HammerTouch | F30: Missed | G30: Hard | M30: 34 | N30: 2026-10-02 15:27:15.410 | Minigame: Alex | Type: HammerTouch | Outcome: Missed | Difficulty: Hard | ExpectedTime: 8.5760 | ActualTime: N/A | TimingOffset: N/A | TimingError: N/A | ReactionTime: N/A | SpatialAccuracy: N/A | DirectionAccuracy: N/A | CorrectHand: N/A
A31: 30 | B31: 2026-10-02 15:27:15.453 | C31: Interaction | D31: Alex | E31: HammerHit | F31: Success | G31: Hard | K31: 0.0073 | M31: 35 | N31: 2026-10-02 15:27:15.453 | Minigame: Alex | Type: HammerHit | Outcome: Success | Difficulty: Hard | ExpectedTime: 8.9600 | ActualTime: 8.9527 | TimingOffset: -0.0073 | TimingError: 0.0073 | ReactionTime: N/A | SpatialAccuracy: N/A | DirectionAccuracy: N/A | CorrectHand: N/A
A32: 31 | B32: 2026-10-02 15:27:15.564 | C32: Interaction | D32: Alex | E32: HammerHit | F32: Success | G32: Hard | M32: 36 | N32: 2026-10-02 15:27:15.564 | Minigame: Alex | Type: HammerHit | Outcome: Success | Difficulty: Hard | ExpectedTime: 8.9600 | ActualTime: N/A | TimingOffset: N/A | TimingError: N/A | ReactionTime: N/A | SpatialAccuracy: N/A | DirectionAccuracy: N/A | CorrectHand: N/A
A33: 32 | B33: 2026-10-02 15:27:15.801 | C33: Interaction | D33: Alex | E33: HammerHit | F33: Success | G33: Hard | K33: 0.0432 | M33: 37 | N33: 2026-10-02 15:27:15.801 | Minigame: Alex | Type: HammerHit | Outcome: Success | Difficulty: Hard | ExpectedTime: 9.3440 | ActualTime: 9.3008 | TimingOffset: -0.0432 | TimingError: 0.0432 | ReactionTime: N/A | SpatialAccuracy: N/A | DirectionAccuracy: N/A | CorrectHand: N/A
A34: 33 | B34: 2026-10-02 15:27:15.829 | C34: Interaction | D34: Alex | E34: HammerTouch | F34: Success | G34: Hard | M34: 38 | N34: 2026-10-02 15:27:15.829 | Minigame: Alex | Type: HammerTouch | Outcome: Success | Difficulty: Hard | ExpectedTime: 9.3440 | ActualTime: N/A | TimingOffset: N/A | TimingError: N/A | ReactionTime: N/A | SpatialAccuracy: N/A | DirectionAccuracy: N/A | CorrectHand: N/A
A35: 34 | B35: 2026-10-02 15:27:16.164 | C35: Interaction | D35: Alex | E35: HammerHit | F35: Success | G35: Hard | K35: 0.065 | M35: 39 | N35: 2026-10-02 15:27:16.164 | Minigame: Alex | Type: HammerHit | Outcome: Success | Difficulty: Hard | ExpectedTime: 9.7280 | ActualTime: 9.6630 | TimingOffset: -0.0650 | TimingError: 0.0650 | ReactionTime: N/A | SpatialAccuracy: N/A | DirectionAccuracy: N/A | CorrectHand: N/A
A36: 35 | B36: 2026-10-02 15:27:16.609 | C36: Interaction | D36: Alex | E36: HammerHit | F36: Success | G36: Hard | K36: 0.0035 | M36: 40 | N36: 2026-10-02 15:27:16.609 | Minigame: Alex | Type: HammerHit | Outcome: Success | Difficulty: Hard | ExpectedTime: 10.1120 | ActualTime: 10.1085 | TimingOffset: -0.0035 | TimingError: 0.0035 | ReactionTime: N/A | SpatialAccuracy: N/A | DirectionAccuracy: N/A | CorrectHand: N/A
A37: 36 | B37: 2026-10-02 15:27:16.929 | C37: Interaction | D37: Alex | E37: HammerTouch | F37: Missed | G37: Hard | M37: 41 | N37: 2026-10-02 15:27:16.929 | Minigame: Alex | Type: HammerTouch | Outcome: Missed | Difficulty: Hard | ExpectedTime: 10.1120 | ActualTime: N/A | TimingOffset: N/A | TimingError: N/A | ReactionTime: N/A | SpatialAccuracy: N/A | DirectionAccuracy: N/A | CorrectHand: N/A
A38: 37 | B38: 2026-10-02 15:27:16.970 | C38: Interaction | D38: Alex | E38: HammerHit | F38: Success | G38: Hard | K38: 0.0253 | M38: 42 | N38: 2026-10-02 15:27:16.970 | Minigame: Alex | Type: HammerHit | Outcome: Success | Difficulty: Hard | ExpectedTime: 10.4960 | ActualTime: 10.4707 | TimingOffset: -0.0253 | TimingError: 0.0253 | ReactionTime: N/A | SpatialAccuracy: N/A | DirectionAccuracy: N/A | CorrectHand: N/A
A39: 38 | B39: 2026-10-02 15:27:17.013 | C39: Interaction | D39: Alex | E39: HammerHit | F39: Success | G39: Hard | M39: 43 | N39: 2026-10-02 15:27:17.013 | Minigame: Alex | Type: HammerHit | Outcome: Success | Difficulty: Hard | ExpectedTime: 10.4960 | ActualTime: N/A | TimingOffset: N/A | TimingError: N/A | ReactionTime: N/A | SpatialAccuracy: N/A | DirectionAccuracy: N/A | CorrectHand: N/A
A40: 39 | B40: 2026-10-02 15:27:17.360 | C40: Interaction | D40: Alex | E40: HammerHit | F40: Success | G40: Hard | K40: 0.0198 | M40: 44 | N40: 2026-10-02 15:27:17.360 | Minigame: Alex | Type: HammerHit | Outcome: Success | Difficulty: Hard | ExpectedTime: 10.8800 | ActualTime: 10.8602 | TimingOffset: -0.0198 | TimingError: 0.0198 | ReactionTime: N/A | SpatialAccuracy: N/A | DirectionAccuracy: N/A | CorrectHand: N/A
...

Sheet Diccionario
A1: Guía de lectura de los registros
A4: Campo | B4: Interpretación | C4: Precaución
A5: IdEvento | B5: Orden de aparición en el archivo | C5: Permite relacionar interacciones, DDA y estados
A6: FechaHora | B6: Fecha y hora del evento | C6: Hora local de la fuente; zona horaria no indicada
A7: Participante | B7: Identificador de la sesión | C7: Conserva el ID de cada TXT para cruces con encuestas
A8: Resultado | B8: Success, Failed o Missed | C8: Se conservan las categorías originales
A9: TipoAccion | B9: Tipo concreto de interacción | C9: HammerTouch y HammerHit se mantienen separados
A10: TiempoEsperado_s | B10: Tiempo objetivo declarado por el log | C10: Segundos según el registro
A11: TiempoReal_s | B11: Tiempo de ejecución declarado por el log | C11: Puede estar ausente incluso con Success
A12: DesfaseTiming_s | B12: Diferencia con signo entre tiempos | C12: Negativo: ejecución anticipada
A13: ErrorTiming_s | B13: Error temporal reportado | C13: Promedio solo de valores disponibles
A14: TiempoReaccion_s | B14: Tiempo de reacción reportado | C14: N/A no debe interpretarse como 0
A15: PrecisionEspacial | B15: Precisión espacial si se registró | C15: Si todos los datos faltan, promedio vacío
... A22: TextoOriginal | B22: Evento tal como estaba en el .txt | C22: Útil ante eventos nuevos/desconocidos
